Workbook

Sheet Read me
A1: Time ships after Chrysalis — design sheet
A2: Built 8 October 2026 from the brainstorm 'time travel spacecraft similar to Chrysalis'. Every number is a live formula over the blue inputs; change a distance, an acceleration, a radius or a mass and the leads, stresses and bills follow.
A4: THE IDEA | B4: Chrysalis is already a time machine, just a slow one of the kind a cesium clock can measure: at 1 g its rim clocks run ~14 ns/day behind the hub, and over its 400-year crossing at ~1% of c the passengers step off about eight days younger than Earth's calendar. So the brief for a time ship is: make the lead bigger, and decide whose clock you're cheating. Keep the five coats, swap the core.
A6: Legend | B6: Blue text = an input you can change. Black = a formula. Green = a link to another sheet. Yellow fill = an assumption worth questioning. The Notes column carries the reasoning and the source for each line.
A8: SHEETS
A9: Four cores | B9: The four designs side by side: what replaces the shuttle bay, the physics status, the lead and the bill (live).
A10: Chrysalis | B10: The baseline as reported: geometry, cruise speed, spin gravity and the clocks aboard, hoop stress (and the Tipler check), the 400-year lead, fuel, people, and what the nose ploughs through.
A11: Lead table | B11: Seven ships (two are yours to play with): ship time, Earth time, lead, peak speed, mass ratio, and the light-time the Lantern needs. Includes a 1 g lead-vs-distance chart.
A12: Tower | B12: The dilation ship: thrust gravity, the engine's power, floors and lifts, the prow-to-stern clock gradient, the ice shield, and the crew's arrival.
A13: Lantern | B13: The wormhole door: the negative-mass bill, how deep the door goes for each ship, and whether a closed timelike curve forms.
A14: Nautilus | B14: The archive ship: how much it can grow from its own spent tankage, the walk back through time, spin balance, and each era's clock.
A15: Vigil | B15: The cold-storage ship: the roster arithmetic, the pods, the speed bonus from a lighter ship, and the 40-watch calendar.
A16: More cores | B16: The second wing (9 Oct 2026): ferry, shed hull, broadcast, homebody — side by side, live.
A17: Pendulum | B17: The ferry: 1 g out and home; the timetable of futures a ticket buys, and the fare that closes the ferry.
A18: Moult | B18: The shed hull: jettison emptied shells before the brake; a quadratic turns casings into cruise speed (0% moult reproduces Chrysalis exactly).
A19: Lighthouse | B19: The broadcast: the voyage as a 404-year slow-motion transmission; Doppler, latency, and photons per second across four light-years.
A20: Sundiver | B20: The homebody: Sun-grazing orbits bank seconds per pass, and the honest verdict — the wheel beats the well 3,900 to 1.
A21: Constants | B21: Physical constants with sources, the shared assumptions (interstellar density, dust ratio), the project's own clocks for scale, and the materials table.
A23: CAVEATS
A24: Chrysalis figures | B24: From press coverage of the Project Hyperion entry (58 km, 6 km, 2.4 billion t, 2,400 people, 400 years, 40 trillion km). The team's own report may differ; the inputs are blue so you can correct them.
A25: Orders of magnitude | B25: The torch rows assume a perfect photon rocket (the floor on the fuel bill). The ice-shield mass is an upper bound (every joule sublimates ice). The wormhole mass is the Morris–Thorne order of magnitude. Hoop stress is for a self-supporting thin shell. None of this is a design; all of it is a sanity check.
A26: Corrections to the spoken version | B26: Three things the formulas overturned. (1) The peak proton flux on the prow is ~300 kW/m², not 100: the ship-frame density is γn. (2) 'The prow is a glacier' fails: a sacrificial ice prow the full width of the ship needs ~66 Gt at n = 1 cm⁻³ (27 ships' worth, a 2.5-km slab), not 30 Mt — so the Tower needs a needle prow, a refractory bow that re-radiates at ~1,500 K, or a magnetic deflector; the Tower sheet now checks the refractory option. (3) The Proxima torch's ship time is 3.5 years at 4.2465 ly (3.6 is the usual round figure). Everything else checks out.
A28: SOURCES
B29: Project Hyperion Design Competition results — https://projecthyperion.org/
B30: Centauri Dreams, 'Chrysalis: Designing a Generation Ship' (12 Aug 2025) — https://www.centauri-dreams.org/2025/08/12/chrysalis-designing-a-generation-ship/
B31: Holistic News, 'This Starship Could Take Us to the Stars' — https://holistic.news/en/journey-to-alpha-centauri-a-ship-is-designed/
B32: ITC.ua, 'Chrysalis: an interstellar ship project to travel 2400 people for 400 years' — https://itc.ua/en/news/chrysalis-an-interstellar-ship-project-to-travel-2400-people-for-400-years
B33: Futura-Sciences, Chrysalis coverage — https://www.futura-sciences.com/en/?p=20696
B34: Interesting Engineering, '36-mile-long cigar-shaped starship' — https://interestingengineering.com/space/engineers-propose-multi-generational-spacecraft
B35: Indian Defence Review, 'No return, no rescue: meet Chrysalis' — https://indiandefencereview.com/no-return-no-rescue-meet-chrysalis-the-36-mile-starship-designed-to-carry-1000-humans-into-deep-space-forever/
B36: Morris, Thorne & Yurtsever, 'Wormholes, Time Machines, and the Weak Energy Condition', Phys. Rev. Lett. 61, 1446 (1988)
B37: Hawking, 'Chronology protection conjecture', Phys. Rev. D 46, 603 (1992)
B38: Tipler, 'Rotating cylinders and the possibility of global causality violation', Phys. Rev. D 9, 2203 (1974)
B39: Vessot et al., Gravity Probe A, Phys. Rev. Lett. 45, 2081 (1980) — 7×10⁻⁵ test of gravitational redshift
B40: The Greylock Time Machine design note — Time Travel project, claude/greylock-time-machine.md
B41: Constants: CODATA 2018; IAU 2015 nominal values; Lee et al., Science 321, 385 (2008) for graphene

Sheet Four cores
A1: Four cores — keep Chrysalis's five coats, swap the core
A2: Chrysalis is five concentric shells around a core that holds the landing shuttles and the main comms. Each design below keeps the shells and replaces the core. Numbers are live links to the other sheets.
B4: TOWER — the engine | C4: LANTERN — the door | D4: NAUTILUS — the archive | E4: VIGIL — the vault
A5: What replaces the shuttle bay | B5: The engine. Thrust is gravity: 'down' is aft and the five shells become stacked floors of a 58-km tower standing on its exhaust. | C5: A wormhole mouth. Its twin stays at the Earth–Moon L1 yard where the ship was built; the core stops being an axis and becomes a point, so the shells nest as spheres round a lantern room. | D5: An archive. Each generation builds the next chamber onto the axis and seals the one it grew up in exactly as it was lived — lights on, cups on the table. | E5: A vault. Cold storage for everyone not on watch; sixty awake at a time in ten-year watches.
A6: Gravity | B6: Thrust, 1 g aft (spin gravity gives way) | C6: Spin | D6: Spin — balanced as the ship grows | E6: Spin
A7: Physics status | B7: Known physics: forward time dilation, measured to 7×10⁻⁵ (Gravity Probe A). The bill is engineering. | C7: Permitted on paper (Morris–Thorne–Yurtsever 1988) but needs negative energy in bulk, which quantum theory forbids. Chronology protection waits past the speed limit. | D7: Known physics: civil engineering and archiving. | E7: Needs reversible human cold storage — the one technology here that does not exist.
A8: Direction of travel | B8: Forward only | C8: Backward — to a moment after the ship left, never before | D8: Forward; the archive lets the future stand in the past, in place | E8: Forward, by skipping
A9: Lead (live) | B9: =Tower!$B$31 -> 2.3 years | C9: =Lantern!$B$22&" — "&Lantern!$B$26 -> 2.3 years — No closed timelike curve: the door is safe | D9: ='Lead table'!$R$5&" (Chrysalis as drawn)" -> 8.2 days (Chrysalis as drawn) | E9: =TEXT(Vigil!$B$29,"0")&" years skipped per person, plus "&'Lead table'!$R$5&" of relativistic lead" -> 390 years skipped per person, plus 8.2 days of relativistic lead
A10: Who ages less | B10: The crew | C10: The ship's mouth, so the door opens onto the past | D10: Nobody to speak of; the time travel is cultural | E10: Everyone asleep
A11: The bill (live) | B11: =TEXT(Tower!$B$32-1,"#,##0")&" t of fuel per t of ship; one Sun per "&TEXT(Tower!$B$50,"#,##0")&" ships at dry mass" -> 38 t of fuel per t of ship; one Sun per 54,252 ships at dry mass | C11: ="About "&TEXT(Lantern!$B$14,"0.0")&" Jupiter masses of negative mass for a "&TEXT(Lantern!$B$7,"0")&" m throat" -> About 1.4 Jupiter masses of negative mass for a 2 m throat | D11: ="Spent tankage builds "&TEXT(Nautilus!$B$31,"0%")&" of the wished-for chambers: "&TEXT(Nautilus!$B$32,"#,##0")&" m per generation is affordable" -> Spent tankage builds 18% of the wished-for chambers: 184 m per generation is affordable | E11: ="Cold storage for "&TEXT(Vigil!$B$33,"#,##0")&" people at a time; "&TEXT(Vigil!$B$35,"#,##0")&" kW to hold them" -> Cold storage for 2,340 people at a time; 351 kW to hold them
A12: The human problem | B12: Nobody is born en route; the crew are the travellers, and no mission control waits at the far end. The ship must carry its own Earth. | C12: It deletes the one thing that defines a generation ship — isolation — and replaces it with something stranger: you can go home whenever you like, but home is always a little in the past. | D12: Deciding what a generation is allowed to leave out. The Hyperion jury said only Chrysalis took intergenerational meaning-making seriously; this is that, built into the hull. | E12: Rip Van Winkle in reverse: each watch is a different century's people, and the sleepers wake as strangers to those who kept them.
A13: Stacks with | B13: Nautilus as its interior; Vigil for the galactic-centre dial | C13: Nautilus | D13: Tower, Lantern | E13: Tower
A14: Sheet | B14: Tower | C14: Lantern | D14: Nautilus | E14: Vigil

Sheet More cores
A1: More cores — the second wing
A2: Four further cores in the same idiom (added 9 October 2026): keep the shells, swap the core. Each column links live to its sheet; the first four are on Four cores.
B4: PENDULUM — the ferry | C4: MOULT — the shed hull | D4: LIGHTHOUSE — the broadcast | E4: SUNDIVER — the homebody
A5: What replaces the shuttle bay | B5: A return engine. The ship swings out and home at 1 g forever; the shells are a terminal, not a colony. | C5: Nothing — that is the point. Each emptied shell is sealed and cast off; the hull that brakes at Proxima is half the hull that launched. | D5: A clock vault and a stern laser. The core broadcasts the crew's slower stream of time home for four centuries. | E5: A heat shield. The ship never leaves the Sun; it dives, and banks.
A6: Gravity | B6: Thrust, 1 g | C6: Spin | D6: Spin | E6: Spin (freefall in the dives)
A7: Physics status | B7: Known physics; the fare is the problem | C7: Known physics; a staging problem | D7: Known physics; nothing new flies at all | E7: Known physics; thermally heroic, temporally feeble
A8: Direction of travel | B8: Forward, round trip — the only core that comes home | C8: Forward | D8: Forward — and outward: it hands the stay-at-homes the voyage in slow motion | E8: Forward, barely
A9: Lead (live) | B9: =Pendulum!$B$20&" per cycle, per rider" -> 15.4 years per cycle, per rider | C9: =TEXT(Moult!$B$19,"0")&" years earlier at Proxima, with "&TEXT(Moult!$B$20,"0.0")&" days of lead" -> 90 years earlier at Proxima, with 10.5 days of lead | D9: ="400 ship-years air over "&TEXT(Lighthouse!$B$16,"0.0")&" Earth-years" -> 400 ship-years air over 404.2 Earth-years | E9: =TEXT(Sundiver!$B$19,"0")&" s banked in "&TEXT(Sundiver!$B$8,"0")&" years of diving" -> 180 s banked in 400 years of diving
A10: Who ages less | B10: The riders, one ticket at a time | C10: The crew — and the cast-off shells least of all | D10: The crew; Earth merely gets to watch | E10: The kettle
A11: The bill (live) | B11: =TEXT(Pendulum!$B$23,"#,##0")&" t of perfect-photon fuel per rider per cycle" -> 30,421,956,655 t of perfect-photon fuel per rider per cycle | C11: =TEXT(Moult!$B$38/1000,"#,##0")&" t of hull cast off — the speed is paid in shells, not fuel" -> 1,200,000,000 t of hull cast off — the speed is paid in shells, not fuel | D11: =TEXT(Lighthouse!$B$24,"#,##0")&" photons per second at Earth from a "&TEXT(Lighthouse!$B$6,"0")&" kW stern light" -> 2,774 photons per second at Earth from a 1 kW stern light | E11: ="A shield at ≥ "&TEXT(Sundiver!$B$20,"#,##0")&" K, forever" -> A shield at ≥ 2,046 K, forever
A12: The human problem | B12: The ferry crew can keep no friendship ashore: every workmate ages a cycle per cycle. | C12: Throwing away the rooms your grandparents lived in is Nautilus's nightmare — Moult and Nautilus cannot both be your culture. | D12: Celebrity without reply: the crew perform their lives for an audience whose answers arrive a childhood later. | E12: None. Nobody rides it; that is the verdict.
A13: Stacks with | B13: Lantern — a mouth at each terminal turns the ferry into a subway | C13: Vigil — each watch seals a shell and sheds it | D13: Every other core: any time ship should carry the Lighthouse as its black box | E13: The Greylock bench — a calibration source, not a ship
A14: Sheet | B14: Pendulum | C14: Moult | D14: Lighthouse | E14: Sundiver

Sheet Chrysalis
A1: Chrysalis as drawn — the baseline
A2: The Project Hyperion winner (i4is, 2025) as reported in press coverage of the entry; the team's own report may differ. Everything below is computed from the blue inputs, so change a number and the clocks, stresses and leads follow.
A5: Inputs, as reported
A6: Quantity | B6: Value | C6: Unit | D6: Notes / source
A7: Length | B7: 58 | C7: km | D7: holistic.news; Interesting Engineering (36 miles)
A8: Diameter | B8: 6 | C8: km | D8: holistic.news
A9: Mass (taken here as the dry, as-built mass) | B9: 2400000000 | C9: tonnes | D9: Indian Defence Review: 'over 2.4 billion tons'
A10: Capacity | B10: 2400 | C10: people | D10: Futura-Sciences; Interesting Engineering
A11: Steady-state population (births planned to hold this) | B11: 1500 | C11: people | D11: Futura-Sciences; holistic.news
A12: Distance to Proxima Centauri b | B12: 40000000000000 | C12: km | D12: itc.ua: '40 trillion kilometres' (Proxima is 4.25 ly = 4.02×10¹³ km)
A13: Journey time, Earth years | B13: 400 | C13: years | D13: itc.ua; holistic.news
A14: Gravity at the outer shell, from spin | B14: 1 | C14: g | D14: The ship rotates for gravity; 1 g at the rim is this sheet's assumption
A15: Nested layers around the core | B15: 5 | D15: Futura-Sciences ('five concentric layers')
A17: Assumptions (edit)
A18: Quantity | B18: Value | C18: Unit | D18: Notes / source
A19: Fusion exhaust velocity, as a fraction of c | B19: 0.0333 | C19: × c | D19: Daedalus-class D–³He exhaust ≈ 10,000 km/s. Chrysalis cites Daedalus-style fusion (Centauri Dreams).
A20: Life expectancy aboard | B20: 85 | C20: years | D20: Assumption
A21: Generation length | B21: 27 | C21: years | D21: Assumption
A22: Earliest launch | B22: 2125 | C22: year | D22: ≈75 years of Antarctic isolation + 20–25 years of construction, counted from now
A23: Boarding age used for the 'age at arrival' lines | B23: 25 | C23: years | D23: Assumption
A24: Tipler check: rim speed a time-machine cylinder would need | B24: 0.5 | C24: × c | D24: Tipler (1974): the surface must turn at more than about half the speed of light — and a finite cylinder needs negative energy anyway (Hawking 1992).
A25: Dust grain mass for the impact line | B25: 1 | C25: mg | D25: Assumption
A27: Geometry and cruise
A28: Quantity | B28: Value | C28: Unit | D28: Notes / source
A29: Radius | B29: =$B$8*1000/2 -> 3000 | C29: m
A30: Length | B30: =$B$7*1000 -> 58000 | C30: m
A31: Mass | B31: =$B$9*1000 -> 2400000000000 | C31: kg
A32: Distance | B32: =$B$12*1000 -> 4e+16 | C32: m
A33: Distance | B33: =$B$32/Constants!$B$12 -> 4.2280033 | C33: light-years
A34: Cruise speed (distance ÷ journey time) | B34: =$B$32/($B$13*Constants!$B$10) -> 3168808.8 | C34: m/s
A35: …in km/s | B35: =$B$34/1000 -> 3168.8088 | C35: km/s
A36: …as a fraction of c (β) | B36: =$B$34/Constants!$B$7 -> 0.010570008 | C36: × c | D36: About 1% of light speed
A37: Lorentz factor γ | B37: =1/SQRT(1-$B$36^2) -> 1.0000559
A39: Spin gravity and the clocks aboard
A40: Quantity | B40: Value | C40: Unit | D40: Notes / source
A41: Rim speed for the chosen gravity, √(g r) | B41: =SQRT($B$14*Constants!$B$8*$B$29) -> 171.52245 | C41: m/s
A42: Rotation period | B42: =2*PI()*$B$29/$B$41 -> 109.89556 | C42: s
A43: …in revolutions per minute | B43: =60/$B$42 -> 0.54597291 | C43: rpm
A44: Rim clock runs slow relative to the hub by v²/2c² | B44: =$B$41^2/(2*Constants!$B$7^2) -> 1.6367055e-13 | C44: fraction | D44: First-order term of 1 − 1/γ; exact to better than one part in 10¹³ here
A45: …as nanoseconds per day | B45: =$B$44*Constants!$B$11*1000000000 -> 14.141135 | C45: ns/day | D45: The spoken figure: 'about 14 ns/day'
...

Sheet Lead table
A1: Lead table — how much younger the ship arrives
A2: Coast rows: constant cruise speed (acceleration phases ignored). Torch rows: constant proper acceleration to the midpoint, flip, brake. Legs = 2 for there-and-back. Lead = Earth time − ship time. Mass ratio uses the relativistic rocket equation M₀/M₁ = exp(φ·c/vₑ) per boost, with one accelerate and one brake per leg. Blue = input, green = link, black = formula. Rows 10–11 are yours to play with.
A4: Ship | B4: Mode | C4: Distance one way (ly) | D4: Legs | E4: Cruise speed β (coast) | F4: Proper accel. (g) (torch) | G4: Exhaust speed βₑ (× c) | H4: c/a (years, torch) | I4: x = a·(d/2)/c² (torch) | J4: Rapidity φ per boost | K4: Peak speed β_max | L4: Peak γ | M4: Ship time per leg (yr) | N4: Earth time per leg (yr) | O4: Ship time total (yr) | P4: Earth time total (yr) | Q4: Lead (yr) | R4: Lead, readable | S4: Boosts | T4: Mass ratio M₀/M₁ | U4: Fuel per tonne of ship (t) | V4: Final separation from Earth (ly) | W4: Light-time Earth↔ship at the end (yr)
A5: Chrysalis as drawn (~1% c) | B5: coast | C5: =Chrysalis!$B$33 -> 4.2280033 | D5: 1 | E5: =Chrysalis!$B$36 -> 0.010570008 | G5: =Chrysalis!$B$19 -> 0.0333 | H5: =IF(B5="torch",Constants!$B$7/(F5*Constants!$B$8)/Constants!$B$10,"") | I5: =IF(B5="torch",F5*Constants!$B$8*(C5*Constants!$B$12/2)/Constants!$B$7^2,"") | J5: =IF(B5="torch",ACOSH(1+I5),ATANH(E5)) -> 0.010570402 | K5: =TANH(J5) -> 0.010570008 | L5: =COSH(J5) -> 1.0000559 | M5: =IF(B5="torch",2*H5*J5,C5/E5/L5) -> 399.97765 | N5: =IF(B5="torch",2*H5*SINH(J5),C5/E5) -> 400 | O5: =D5*M5 -> 399.97765 | P5: =D5*N5 -> 400 | Q5: =P5-O5 -> 0.022345639 | R5: =IF(Q5<1/12,TEXT(Q5*365.25,"0.0")&" days",IF(Q5<1,TEXT(Q5*12,"0.0")&" months",IF(Q5<10,TEXT(Q5,"0.0")&" years",TEXT(Q5,"#,##0")&" years"))) -> 8.2 days | S5: =2*D5 -> 2 | T5: =EXP(S5*J5/G5) -> 1.8867561 | U5: =T5-1 -> 0.88675605 | V5: =IF(D5=1,C5,0) -> 4.2280033 | W5: =V5*Constants!$B$12/Constants!$B$7/Constants!$B$10 -> 4.2280033
A6: Fusion pushed to Daedalus speed (0.1 c) | B6: coast | C6: 4.2465 | D6: 1 | E6: 0.1 | G6: 0.0333 | H6: =IF(B6="torch",Constants!$B$7/(F6*Constants!$B$8)/Constants!$B$10,"") | I6: =IF(B6="torch",F6*Constants!$B$8*(C6*Constants!$B$12/2)/Constants!$B$7^2,"") | J6: =IF(B6="torch",ACOSH(1+I6),ATANH(E6)) -> 0.10033535 | K6: =TANH(J6) -> 0.1 | L6: =COSH(J6) -> 1.0050378 | M6: =IF(B6="torch",2*H6*J6,C6/E6/L6) -> 42.252142 | N6: =IF(B6="torch",2*H6*SINH(J6),C6/E6) -> 42.465 | O6: =D6*M6 -> 42.252142 | P6: =D6*N6 -> 42.465 | Q6: =P6-O6 -> 0.21285848 | R6: =IF(Q6<1/12,TEXT(Q6*365.25,"0.0")&" days",IF(Q6<1,TEXT(Q6*12,"0.0")&" months",IF(Q6<10,TEXT(Q6,"0.0")&" years",TEXT(Q6,"#,##0")&" years"))) -> 2.6 months | S6: =2*D6 -> 2 | T6: =EXP(S6*J6/G6) -> 414.11637 | U6: =T6-1 -> 413.11637 | V6: =IF(D6=1,C6,0) -> 4.2465 | W6: =V6*Constants!$B$12/Constants!$B$7/Constants!$B$10 -> 4.2465
A7: 1 g torch to Proxima | B7: torch | C7: 4.2465 | D7: 1 | F7: 1 | G7: 1 | H7: =IF(B7="torch",Constants!$B$7/(F7*Constants!$B$8)/Constants!$B$10,"") -> 0.96871508 | I7: =IF(B7="torch",F7*Constants!$B$8*(C7*Constants!$B$12/2)/Constants!$B$7^2,"") -> 2.1918209 | J7: =IF(B7="torch",ACOSH(1+I7),ATANH(E7)) -> 1.8282435 | K7: =TANH(J7) -> 0.94965395 | L7: =COSH(J7) -> 3.1918209 | M7: =IF(B7="torch",2*H7*J7,C7/E7/L7) -> 3.542094 | N7: =IF(B7="torch",2*H7*SINH(J7),C7/E7) -> 5.8725937 | O7: =D7*M7 -> 3.542094 | P7: =D7*N7 -> 5.8725937 | Q7: =P7-O7 -> 2.3304996 | R7: =IF(Q7<1/12,TEXT(Q7*365.25,"0.0")&" days",IF(Q7<1,TEXT(Q7*12,"0.0")&" months",IF(Q7<10,TEXT(Q7,"0.0")&" years",TEXT(Q7,"#,##0")&" years"))) -> 2.3 years | S7: =2*D7 -> 2 | T7: =EXP(S7*J7/G7) -> 38.725061 | U7: =T7-1 -> 37.725061 | V7: =IF(D7=1,C7,0) -> 4.2465 | W7: =V7*Constants!$B$12/Constants!$B$7/Constants!$B$10 -> 4.2465
A8: 1 g, 1,000 ly and back | B8: torch | C8: 1000 | D8: 2 | F8: 1 | G8: 1 | H8: =IF(B8="torch",Constants!$B$7/(F8*Constants!$B$8)/Constants!$B$10,"") -> 0.96871508 | I8: =IF(B8="torch",F8*Constants!$B$8*(C8*Constants!$B$12/2)/Constants!$B$7^2,"") -> 516.14764 | J8: =IF(B8="torch",ACOSH(1+I8),ATANH(E8)) -> 6.9414746 | K8: =TANH(J8) -> 0.99999813 | L8: =COSH(J8) -> 517.14764 | M8: =IF(B8="torch",2*H8*J8,C8/E8/L8) -> 13.448622 | N8: =IF(B8="torch",2*H8*SINH(J8),C8/E8) -> 1001.9356 | O8: =D8*M8 -> 26.897245 | P8: =D8*N8 -> 2003.8711 | Q8: =P8-O8 -> 1976.9739 | R8: =IF(Q8<1/12,TEXT(Q8*365.25,"0.0")&" days",IF(Q8<1,TEXT(Q8*12,"0.0")&" months",IF(Q8<10,TEXT(Q8,"0.0")&" years",TEXT(Q8,"#,##0")&" years"))) -> 1,977 years | S8: =2*D8 -> 4 | T8: =EXP(S8*J8/G8) -> 1.1443965e+12 | U8: =T8-1 -> 1.1443965e+12 | V8: =IF(D8=1,C8,0) -> 0 | W8: =V8*Constants!$B$12/Constants!$B$7/Constants!$B$10 -> 0
A9: 1 g to the galactic centre | B9: torch | C9: 26000 | D9: 1 | F9: 1 | G9: 1 | H9: =IF(B9="torch",Constants!$B$7/(F9*Constants!$B$8)/Constants!$B$10,"") -> 0.96871508 | I9: =IF(B9="torch",F9*Constants!$B$8*(C9*Constants!$B$12/2)/Constants!$B$7^2,"") -> 13419.839 | J9: =IF(B9="torch",ACOSH(1+I9),ATANH(E9)) -> 10.197711 | K9: =TANH(J9) -> 1 | L9: =COSH(J9) -> 13420.839 | M9: =IF(B9="torch",2*H9*J9,C9/E9/L9) -> 19.757353 | N9: =IF(B9="torch",2*H9*SINH(J9),C9/E9) -> 26001.937 | O9: =D9*M9 -> 19.757353 | P9: =D9*N9 -> 26001.937 | Q9: =P9-O9 -> 25982.18 | R9: =IF(Q9<1/12,TEXT(Q9*365.25,"0.0")&" days",IF(Q9<1,TEXT(Q9*12,"0.0")&" months",IF(Q9<10,TEXT(Q9,"0.0")&" years",TEXT(Q9,"#,##0")&" years"))) -> 25,982 years | S9: =2*D9 -> 2 | T9: =EXP(S9*J9/G9) -> 7.2047563e+08 | U9: =T9-1 -> 7.2047563e+08 | V9: =IF(D9=1,C9,0) -> 26000 | W9: =V9*Constants!$B$12/Constants!$B$7/Constants!$B$10 -> 26000
A10: Your ship A (torch) | B10: torch | C10: 100 | D10: 1 | F10: 0.5 | G10: 1 | H10: =IF(B10="torch",Constants!$B$7/(F10*Constants!$B$8)/Constants!$B$10,"") -> 1.9374302 | I10: =IF(B10="torch",F10*Constants!$B$8*(C10*Constants!$B$12/2)/Constants!$B$7^2,"") -> 25.807382 | J10: =IF(B10="torch",ACOSH(1+I10),ATANH(E10)) -> 3.9814764 | K10: =TANH(J10) -> 0.99930399 | L10: =COSH(J10) -> 26.807382 | M10: =IF(B10="torch",2*H10*J10,C10/E10/L10) -> 15.427665 | N10: =IF(B10="torch",2*H10*SINH(J10),C10/E10) -> 103.80256 | O10: =D10*M10 -> 15.427665 | P10: =D10*N10 -> 103.80256 | Q10: =P10-O10 -> 88.374898 | R10: =IF(Q10<1/12,TEXT(Q10*365.25,"0.0")&" days",IF(Q10<1,TEXT(Q10*12,"0.0")&" months",IF(Q10<10,TEXT(Q10,"0.0")&" years",TEXT(Q10,"#,##0")&" years"))) -> 88 years | S10: =2*D10 -> 2 | T10: =EXP(S10*J10/G10) -> 2872.5425 | U10: =T10-1 -> 2871.5425 | V10: =IF(D10=1,C10,0) -> 100 | W10: =V10*Constants!$B$12/Constants!$B$7/Constants!$B$10 -> 100
A11: Your ship B (coast) | B11: coast | C11: 4.2465 | D11: 1 | E11: 0.5 | G11: 1 | H11: =IF(B11="torch",Constants!$B$7/(F11*Constants!$B$8)/Constants!$B$10,"") | I11: =IF(B11="torch",F11*Constants!$B$8*(C11*Constants!$B$12/2)/Constants!$B$7^2,"") | J11: =IF(B11="torch",ACOSH(1+I11),ATANH(E11)) -> 0.54930614 | K11: =TANH(J11) -> 0.5 | L11: =COSH(J11) -> 1.1547005 | M11: =IF(B11="torch",2*H11*J11,C11/E11/L11) -> 7.3551538 | N11: =IF(B11="torch",2*H11*SINH(J11),C11/E11) -> 8.493 | O11: =D11*M11 -> 7.3551538 | P11: =D11*N11 -> 8.493 | Q11: =P11-O11 -> 1.1378462 | R11: =IF(Q11<1/12,TEXT(Q11*365.25,"0.0")&" days",IF(Q11<1,TEXT(Q11*12,"0.0")&" months",IF(Q11<10,TEXT(Q11,"0.0")&" years",TEXT(Q11,"#,##0")&" years"))) -> 1.1 years | S11: =2*D11 -> 2 | T11: =EXP(S11*J11/G11) -> 3 | U11: =T11-1 -> 2 | V11: =IF(D11=1,C11,0) -> 4.2465 | W11: =V11*Constants!$B$12/Constants!$B$7/Constants!$B$10 -> 4.2465
A13: Formulas: torch — x = a(d/2)/c², φ = acosh(1+x), ship time per leg τ = 2(c/a)φ, Earth time per leg t = 2(c/a)sinh φ, β_max = tanh φ, γ_max = 1+x. Coast — φ = atanh β, t = d/v, τ = t/γ. Mass ratio per boost = exp(φ c/vₑ); boosts = 2 per leg.
A14: βₑ = 1 is a perfect photon rocket (antimatter, perfectly collimated, no waste heat) — the floor on the fuel bill, not an engine anyone has. βₑ = 0.0333 is Daedalus-class fusion.
A15: The Chrysalis row (as drawn) reads its speed, distance and exhaust from the Chrysalis sheet. 'Legs = 2' leaves the ship back at Earth, which is what turns a Lantern door into a closed timelike curve (see the Lantern sheet).
A17: A 1 g ship, one way with braking: times vs distance (chart data)
A18: One-way distance (ly) | B18: Ship time (yr) | C18: Earth time (yr) | D18: Lead (yr)
A19: 1 | B19: =2*(Constants!$B$7/Constants!$B$8/Constants!$B$10)*ACOSH(1+Constants!$B$8*(A19*Constants!$B$12/2)/Constants!$B$7^2) -> 1.8923438 | C19: =2*(Constants!$B$7/Constants!$B$8/Constants!$B$10)*SINH(ACOSH(1+Constants!$B$8*(A19*Constants!$B$12/2)/Constants!$B$7^2)) -> 2.2079086 | D19: =C19-B19 -> 0.3155648
A20: 2 | B20: =2*(Constants!$B$7/Constants!$B$8/Constants!$B$10)*ACOSH(1+Constants!$B$8*(A20*Constants!$B$12/2)/Constants!$B$7^2) -> 2.5872559 | C20: =2*(Constants!$B$7/Constants!$B$8/Constants!$B$10)*SINH(ACOSH(1+Constants!$B$8*(A20*Constants!$B$12/2)/Constants!$B$7^2)) -> 3.4277866 | D20: =C20-B20 -> 0.84053062
A21: 4.2465 | B21: =2*(Constants!$B$7/Constants!$B$8/Constants!$B$10)*ACOSH(1+Constants!$B$8*(A21*Constants!$B$12/2)/Constants!$B$7^2) -> 3.542094 | C21: =2*(Constants!$B$7/Constants!$B$8/Constants!$B$10)*SINH(ACOSH(1+Constants!$B$8*(A21*Constants!$B$12/2)/Constants!$B$7^2)) -> 5.8725937 | D21: =C21-B21 -> 2.3304996
A22: 10 | B22: =2*(Constants!$B$7/Constants!$B$8/Constants!$B$10)*ACOSH(1+Constants!$B$8*(A22*Constants!$B$12/2)/Constants!$B$7^2) -> 4.852899 | C22: =2*(Constants!$B$7/Constants!$B$8/Constants!$B$10)*SINH(ACOSH(1+Constants!$B$8*(A22*Constants!$B$12/2)/Constants!$B$7^2)) -> 11.77916 | D22: =C22-B22 -> 6.9262607
A23: 30 | B23: =2*(Constants!$B$7/Constants!$B$8/Constants!$B$10)*ACOSH(1+Constants!$B$8*(A23*Constants!$B$12/2)/Constants!$B$7^2) -> 6.7706251 | C23: =2*(Constants!$B$7/Constants!$B$8/Constants!$B$10)*SINH(ACOSH(1+Constants!$B$8*(A23*Constants!$B$12/2)/Constants!$B$7^2)) -> 31.878611 | D23: =C23-B23 -> 25.107985
A24: 100 | B24: =2*(Constants!$B$7/Constants!$B$8/Constants!$B$10)*ACOSH(1+Constants!$B$8*(A24*Constants!$B$12/2)/Constants!$B$7^2) -> 9.0207787 | C24: =2*(Constants!$B$7/Constants!$B$8/Constants!$B$10)*SINH(ACOSH(1+Constants!$B$8*(A24*Constants!$B$12/2)/Constants!$B$7^2)) -> 101.91902 | D24: =C24-B24 -> 92.898238
A25: 300 | B25: =2*(Constants!$B$7/Constants!$B$8/Constants!$B$10)*ACOSH(1+Constants!$B$8*(A25*Constants!$B$12/2)/Constants!$B$7^2) -> 11.124713 | C25: =2*(Constants!$B$7/Constants!$B$8/Constants!$B$10)*SINH(ACOSH(1+Constants!$B$8*(A25*Constants!$B$12/2)/Constants!$B$7^2)) -> 301.93121 | D25: =C25-B25 -> 290.8065
A26: 1000 | B26: =2*(Constants!$B$7/Constants!$B$8/Constants!$B$10)*ACOSH(1+Constants!$B$8*(A26*Constants!$B$12/2)/Constants!$B$7^2) -> 13.448622 | C26: =2*(Constants!$B$7/Constants!$B$8/Constants!$B$10)*SINH(ACOSH(1+Constants!$B$8*(A26*Constants!$B$12/2)/Constants!$B$7^2)) -> 1001.9356 | D26: =C26-B26 -> 988.48693
A27: 3000 | B27: =2*(Constants!$B$7/Constants!$B$8/Constants!$B$10)*ACOSH(1+Constants!$B$8*(A27*Constants!$B$12/2)/Constants!$B$7^2) -> 15.574609 | C27: =2*(Constants!$B$7/Constants!$B$8/Constants!$B$10)*SINH(ACOSH(1+Constants!$B$8*(A27*Constants!$B$12/2)/Constants!$B$7^2)) -> 3001.9368 | D27: =C27-B27 -> 2986.3622
A28: 10000 | B28: =2*(Constants!$B$7/Constants!$B$8/Constants!$B$10)*ACOSH(1+Constants!$B$8*(A28*Constants!$B$12/2)/Constants!$B$7^2) -> 17.906347 | C28: =2*(Constants!$B$7/Constants!$B$8/Constants!$B$10)*SINH(ACOSH(1+Constants!$B$8*(A28*Constants!$B$12/2)/Constants!$B$7^2)) -> 10001.937 | D28: =C28-B28 -> 9984.0309
A29: 26000 | B29: =2*(Constants!$B$7/Constants!$B$8/Constants!$B$10)*ACOSH(1+Constants!$B$8*(A29*Constants!$B$12/2)/Constants!$B$7^2) -> 19.757353 | C29: =2*(Constants!$B$7/Constants!$B$8/Constants!$B$10)*SINH(ACOSH(1+Constants!$B$8*(A29*Constants!$B$12/2)/Constants!$B$7^2)) -> 26001.937 | D29: =C29-B29 -> 25982.18
A30: 100000 | B30: =2*(Constants!$B$7/Constants!$B$8/Constants!$B$10)*ACOSH(1+Constants!$B$8*(A30*Constants!$B$12/2)/Constants!$B$7^2) -> 22.367107 | C30: =2*(Constants!$B$7/Constants!$B$8/Constants!$B$10)*SINH(ACOSH(1+Constants!$B$8*(A30*Constants!$B$12/2)/Constants!$B$7^2)) -> 100001.94 | D30: =C30-B30 -> 99979.57

Sheet Tower
A1: Tower — the honest one: the core is the engine
A2: A time ship in known physics is a dilation ship, and a dilation ship thrusts for most of the trip. Spin gravity gives way to thrust gravity: 'down' is aft, the nested shells become stacked floors, and the ship is a 58-km-tall building standing on its exhaust. Pick a ship from the Lead table in the dropdown; everything below follows it.
A5: Choose the ship (dropdown) and the assumptions
A6: Quantity | B6: Value | C6: Unit | D6: Notes / source
A7: Ship (any name from the Lead table) | B7: 1 g torch to Proxima | D7: Dropdown — rows of the Lead table
A8: Floor pitch | B8: 5 | C8: m | D8: Assumption
A9: Express-lift speed | B9: 10 | C9: m/s | D9: Fast skyscraper lifts do ~10 m/s
A10: Ice: latent heat of sublimation | B10: 2830000 | C10: J/kg | D10: ≈2.83 MJ/kg; ignores sensible heating from storage temperature, so the ice figures are slightly generous to the ship
A11: Ship dry mass | B11: =Chrysalis!$B$31 -> 2400000000000 | C11: kg | D11: From the Chrysalis sheet
A12: Nose / footprint radius | B12: =Chrysalis!$B$29 -> 3000 | C12: m | D12: From the Chrysalis sheet
A13: Height of the tower (the ship's length) | B13: =Chrysalis!$B$30 -> 58000 | C13: m | D13: From the Chrysalis sheet
A14: Travellers aboard | B14: =Chrysalis!$B$10 -> 2400 | C14: people | D14: Chrysalis capacity; nobody is born en route
A15: Launch year | B15: =Chrysalis!$B$22 -> 2125 | C15: year
A16: Boarding age | B16: =Chrysalis!$B$23 -> 25 | C16: years
A18: Pulled from the Lead table for the chosen ship
A19: Quantity | B19: Value | C19: Unit | D19: Notes / source
A20: Row index in the Lead table | B20: =MATCH($B$7,'Lead table'!$A$5:$A$11,0) -> 3
A21: Mode | B21: =INDEX('Lead table'!$B$5:$B$11,$B$20) -> torch
A22: Proper acceleration | B22: =INDEX('Lead table'!$F$5:$F$11,$B$20) -> 1 | C22: g | D22: Blank for a coast row: the thrust-gravity block below then reads zero
A23: Distance one way | B23: =INDEX('Lead table'!$C$5:$C$11,$B$20) -> 4.2465 | C23: ly
A24: Legs | B24: =INDEX('Lead table'!$D$5:$D$11,$B$20) -> 1
A25: Rapidity per boost φ | B25: =INDEX('Lead table'!$J$5:$J$11,$B$20) -> 1.8282435
A26: Peak speed β_max | B26: =INDEX('Lead table'!$K$5:$K$11,$B$20) -> 0.94965395 | C26: × c
A27: Peak γ | B27: =INDEX('Lead table'!$L$5:$L$11,$B$20) -> 3.1918209
A28: Ship time, total | B28: =INDEX('Lead table'!$O$5:$O$11,$B$20) -> 3.542094 | C28: years
A29: Earth time, total | B29: =INDEX('Lead table'!$P$5:$P$11,$B$20) -> 5.8725937 | C29: years
A30: Lead | B30: =INDEX('Lead table'!$Q$5:$Q$11,$B$20) -> 2.3304996 | C30: years
A31: Lead, readable | B31: =INDEX('Lead table'!$R$5:$R$11,$B$20) -> 2.3 years
A32: Mass ratio M₀/M₁ | B32: =INDEX('Lead table'!$T$5:$T$11,$B$20) -> 38.725061 | C32: ×
A34: Thrust gravity — the structure is cheap on paper
A35: Quantity | B35: Value | C35: Unit | D35: Notes / source
A36: Acceleration | B36: =IF(ISNUMBER($B$22),$B$22*Constants!$B$8,0) -> 9.80665 | C36: m/s²
A37: Ship's weight under thrust, M·a (= the thrust at dry mass) | B37: =$B$11*$B$36 -> 23535960000000 | C37: N | D37: The spoken figure: 2.4×10¹³ N at 1 g
A38: Footprint π r² | B38: =PI()*$B$12^2 -> 28274334 | C38: m²
A39: Pressure on the base | B39: =$B$37/$B$38 -> 832414.31 | C39: Pa
A40: …in MPa | B40: =$B$39/1000000 -> 0.83241431 | C40: MPa | D40: Under 1 MPa: the spoken 'less than a bike tyre'
A41: …in road-bike tyres | B41: =$B$40/Constants!$B$31 -> 1.1891633 | C41: tyres
A42: …as a fraction of steel's yield strength | B42: =$B$40/Constants!$C$45 -> 0.0033296572 | D42: If the whole base were a solid steel plate; the hard part is funnelling the thrust into one engine, not holding the building up
A44: The engine — a perfect photon rocket (the floor on the bill)
A45: Quantity | B45: Value | C45: Unit | D45: Notes / source
...

Sheet Lantern
A1: Lantern — the door: the core is a wormhole mouth
A2: The one backward route general relativity allows on paper (Morris, Thorne & Yurtsever 1988): hold a throat open with negative energy, leave one mouth at the Earth–Moon L1 yard where the ship is assembled, carry the other in the hub where Chrysalis keeps its comms. The throat keeps the two mouths in step by proper time, so every day of lead the ship banks becomes a day the door opens into the past.
A5: Inputs
A6: Quantity | B6: Value | C6: Unit | D6: Notes / source
A7: Throat radius (a person-sized door) | B7: 2 | C7: m | D7: Assumption
A8: Ship carrying the far mouth (dropdown) | B8: 1 g torch to Proxima | D8: Any name from the Lead table
A9: Home mouth stays at | B9: Earth–Moon L1 assembly yard | D9: Where Chrysalis is built (Interesting Engineering)
A11: The bill nobody can pay
A12: Quantity | B12: Value | C12: Unit | D12: Notes / source
A13: Negative mass needed, of order c²·r/G | B13: =Constants!$B$7^2*$B$7/Constants!$B$9 -> 2.6931818e+27 | C13: kg (negative) | D13: Order-of-magnitude for a Morris–Thorne throat: |M| ~ c² r / G. Quantum field theory allows negative energy only in tiny, fleeting amounts.
A14: …in Jupiter masses | B14: =$B$13/Constants!$B$18 -> 1.4188083 | C14: Jupiters | D14: The spoken 'a Jupiter per metre of throat'
A15: …in Earth masses | B15: =$B$13/Constants!$B$17 -> 450.95306 | C15: Earths
A16: Per metre of throat radius | B16: =Constants!$B$7^2/Constants!$B$9/Constants!$B$18 -> 0.70940413 | C16: Jupiters/m
A18: How deep the door goes — for the chosen ship
A19: Quantity | B19: Value | C19: Unit | D19: Notes / source
A20: Row index in the Lead table | B20: =MATCH($B$8,'Lead table'!$A$5:$A$11,0) -> 3
A21: Lead banked by the ship (Earth time − ship time) | B21: =INDEX('Lead table'!$Q$5:$Q$11,$B$20) -> 2.3304996 | C21: years
A22: …readable | B22: =INDEX('Lead table'!$R$5:$R$11,$B$20) -> 2.3 years | D22: Step into the ship's mouth and you come out of the home mouth this much earlier in Earth's calendar — after the ship left, never before
A23: Separation of the mouths at the end | B23: =INDEX('Lead table'!$V$5:$V$11,$B$20) -> 4.2465 | C23: ly
A24: Light-time between the mouths through ordinary space | B24: =INDEX('Lead table'!$W$5:$W$11,$B$20) -> 4.2465 | C24: years | D24: A radio message takes this long; the door takes no time at all
A25: Safety margin: light-time − lead | B25: =$B$24-$B$21 -> 1.9160004 | C25: years | D25: Positive: no closed timelike curve can form. Negative: the door plus a light-speed trip back closes a loop in time.
A26: Chronology status | B26: =IF($B$25>0,"No closed timelike curve: the door is safe","Closed timelike curve forms: chronology-protection territory") -> No closed timelike curve: the door is safe | D26: Keeping the lag shorter than the light-time between the mouths is the built-in speed limit (Morris–Thorne–Yurtsever 1988; Hawking 1992)
A27: Deepest safe door for this separation | B27: =$B$24 -> 4.2465 | C27: years | D27: Equal to the light-time; any deeper and a loop closes
A29: All seven ships at once
A30: Ship | B30: Door depth (yr) | C30: Light-time (yr) | D30: Verdict
A31: ='Lead table'!$A$5 -> Chrysalis as drawn (~1% c) | B31: ='Lead table'!$Q$5 -> 0.022345639 | C31: ='Lead table'!$W$5 -> 4.2280033 | D31: =IF(C31>B31,"Safe door — "&'Lead table'!$R$5&" into the past","CLOSED TIMELIKE CURVE — "&'Lead table'!$R$5&" of lead with no light-time to hide it") -> Safe door — 8.2 days into the past
A32: ='Lead table'!$A$6 -> Fusion pushed to Daedalus speed (0.1 c) | B32: ='Lead table'!$Q$6 -> 0.21285848 | C32: ='Lead table'!$W$6 -> 4.2465 | D32: =IF(C32>B32,"Safe door — "&'Lead table'!$R$6&" into the past","CLOSED TIMELIKE CURVE — "&'Lead table'!$R$6&" of lead with no light-time to hide it") -> Safe door — 2.6 months into the past
A33: ='Lead table'!$A$7 -> 1 g torch to Proxima | B33: ='Lead table'!$Q$7 -> 2.3304996 | C33: ='Lead table'!$W$7 -> 4.2465 | D33: =IF(C33>B33,"Safe door — "&'Lead table'!$R$7&" into the past","CLOSED TIMELIKE CURVE — "&'Lead table'!$R$7&" of lead with no light-time to hide it") -> Safe door — 2.3 years into the past
A34: ='Lead table'!$A$8 -> 1 g, 1,000 ly and back | B34: ='Lead table'!$Q$8 -> 1976.9739 | C34: ='Lead table'!$W$8 -> 0 | D34: =IF(C34>B34,"Safe door — "&'Lead table'!$R$8&" into the past","CLOSED TIMELIKE CURVE — "&'Lead table'!$R$8&" of lead with no light-time to hide it") -> CLOSED TIMELIKE CURVE — 1,977 years of lead with no light-time to hide it
A35: ='Lead table'!$A$9 -> 1 g to the galactic centre | B35: ='Lead table'!$Q$9 -> 25982.18 | C35: ='Lead table'!$W$9 -> 26000 | D35: =IF(C35>B35,"Safe door — "&'Lead table'!$R$9&" into the past","CLOSED TIMELIKE CURVE — "&'Lead table'!$R$9&" of lead with no light-time to hide it") -> Safe door — 25,982 years into the past
A36: ='Lead table'!$A$10 -> Your ship A (torch) | B36: ='Lead table'!$Q$10 -> 88.374898 | C36: ='Lead table'!$W$10 -> 100 | D36: =IF(C36>B36,"Safe door — "&'Lead table'!$R$10&" into the past","CLOSED TIMELIKE CURVE — "&'Lead table'!$R$10&" of lead with no light-time to hide it") -> Safe door — 88 years into the past
A37: ='Lead table'!$A$11 -> Your ship B (coast) | B37: ='Lead table'!$Q$11 -> 1.1378462 | C37: ='Lead table'!$W$11 -> 4.2465 | D37: =IF(C37>B37,"Safe door — "&'Lead table'!$R$11&" into the past","CLOSED TIMELIKE CURVE — "&'Lead table'!$R$11&" of lead with no light-time to hide it") -> Safe door — 1.1 years into the past
A38: Chrysalis as drawn with a wormhole in the hold is a door eight days into the past; the 1 g Proxima version is a door 2.3 years deep. The 1,000-ly round trip brings the mouth home with a two-millennium lag and zero separation — the textbook wormhole time machine, and exactly where chronology protection says the vacuum blows up.
A39: What it does to a generation ship: it deletes the one thing that defines one — isolation — and replaces it with something stranger. You can go home whenever you like, but home is always a little in the past.

Sheet Nautilus
A1: Nautilus — time as cargo: the core is an archive
A2: No new physics. Chrysalis nests its shells in space; Nautilus nests them in time. Each generation builds the next chamber onto the axis and seals the one it grew up in exactly as it was lived, so the ship arrives longer than it left — a line of sealed eras you can walk back through.
A5: Inputs
A6: Quantity | B6: Value | C6: Unit | D6: Notes / source
A7: Wished-for chamber length per generation | B7: 1000 | C7: m | D7: Assumption
A8: Empty tankage mass per kg of fuel it held | B8: 0.05 | C8: kg/kg | D8: Cryogenic tanks run ~5–10% of the propellant mass; this is the 'slag' the chambers are built from
A9: Radius of the archive ring (sealed chambers sit inboard of the living rim) | B9: 2000 | C9: m | D9: Assumption
A10: Generation length | B10: =Chrysalis!$B$21 -> 27 | C10: years | D10: Chrysalis sheet
A11: Journey | B11: =Chrysalis!$B$13 -> 400 | C11: years | D11: Chrysalis sheet
A12: Ship length at launch | B12: =Chrysalis!$B$30 -> 58000 | C12: m | D12: Chrysalis sheet
A13: Ship dry mass | B13: =Chrysalis!$B$31 -> 2400000000000 | C13: kg | D13: Chrysalis sheet
A14: Rim radius | B14: =Chrysalis!$B$29 -> 3000 | C14: m | D14: Chrysalis sheet
A15: Rim speed | B15: =Chrysalis!$B$41 -> 171.52245 | C15: m/s | D15: Chrysalis sheet
A16: Rim gravity | B16: =Chrysalis!$B$14 -> 1 | C16: g | D16: Chrysalis sheet
A17: Fuel mass burned on the way | B17: =Chrysalis!$B$80 -> 2.1281075e+12 | C17: kg | D17: Chrysalis sheet
A18: Everything the nose sweeps up in the whole crossing (gas + dust) | B18: =Chrysalis!$B$93+Chrysalis!$B$94 -> 1910.6077 | C18: kg | D18: 'Whatever it mines en route' is this: a rounding error. The building stock has to be the ship's own spent tankage.
A20: Growing the ship
A21: Quantity | B21: Value | C21: Unit | D21: Notes / source
A22: Generations over the journey | B22: =$B$11/$B$10 -> 14.814815
A23: Sealed chambers at arrival | B23: =INT($B$22) -> 14
A24: Hull mass per metre of ship, as built | B24: =$B$13/$B$12 -> 41379310 | C24: kg/m
A25: Mass of one wished-for chamber | B25: =$B$24*$B$7 -> 4.137931e+10 | C25: kg
A26: …for all chambers | B26: =$B$25*$B$23 -> 5.7931034e+11 | C26: kg
A27: Length added by arrival | B27: =$B$7*$B$23 -> 14000 | C27: m
A28: Length at arrival | B28: =($B$12+$B$27)/1000 -> 72 | C28: km | D28: The ship arrives longer than it left
A29: Growth | B29: =$B$27/$B$12 -> 0.24137931
A30: Building stock: spent tankage | B30: =$B$17*$B$8 -> 1.0640537e+11 | C30: kg
A31: Share of the wished-for chambers the stock can build | B31: =$B$30/$B$26 -> 0.18367594 | D31: Below 100%, the chambers must be shorter or thinner-walled than the original hull
A32: Affordable chamber length per generation, built like the hull | B32: =$B$30/$B$24/$B$23 -> 183.67594 | C32: m
A33: …total archive length at arrival | B33: =$B$32*$B$23 -> 2571.4632 | C33: m
A35: Walking back through time
A36: Quantity | B36: Value | C36: Unit | D36: Notes / source
A37: Metres of ship per year of history (wished-for chambers) | B37: =$B$7/$B$10 -> 37.037037 | C37: m/yr
A38: …centimetres per day | B38: =$B$37*100/365.25 -> 10.140188 | C38: cm/day
A39: Walk from the newest chamber to year 0 | B39: =$B$27/1000 -> 14 | C39: km
A40: Same walk with the affordable chambers | B40: =$B$33/1000 -> 2.5714632 | C40: km
A42: Spin balance as it grows
A43: Quantity | B43: Value | C43: Unit | D43: Notes / source
A44: Energy to spin up one chamber to rim speed, ½mv² | B44: =0.5*$B$25*$B$15^2 -> 608688620689655 | C44: J
A45: …in GWh | B45: =$B$44/3600000000000 -> 169.08017 | C45: GWh | D45: About a day of a large power station per chamber
...

Sheet Vigil
A1: Vigil — pupation: the core is a vault
A2: The slowest time machine: sleep through it. Everyone Chrysalis can carry goes into cold storage (the one piece of technology here that nobody has) and the ship is tended by a small watch at a time. The watch roster is the ship's calendar.
A5: Inputs
A6: Quantity | B6: Value | C6: Unit | D6: Notes / source
A7: People aboard | B7: =Chrysalis!$B$10 -> 2400 | C7: people | D7: Chrysalis capacity
A8: Awake at any one time | B8: 60 | C8: people | D8: Assumption
A9: Watch length | B9: 10 | C9: years | D9: Assumption
A10: Journey | B10: =Chrysalis!$B$13 -> 400 | C10: years | D10: Chrysalis sheet
A11: Volume per storage pod | B11: 3 | C11: m³ | D11: Assumption
A12: Holding power per pod | B12: 150 | C12: W | D12: Assumption — cryostat losses plus monitoring
A13: Pressurised volume per awake person (quarters, farms, commons) | B13: 300 | C13: m³ | D13: Assumption
A14: Share of the ship's dry mass that scales with pressurised volume | B14: 0.5 | D14: Assumption
A15: Launch year | B15: =Chrysalis!$B$22 -> 2125 | C15: year | D15: Chrysalis sheet
A16: Boarding age | B16: =Chrysalis!$B$23 -> 25 | C16: years | D16: Chrysalis sheet
A17: Ship dry mass | B17: =Chrysalis!$B$31 -> 2400000000000 | C17: kg | D17: Chrysalis sheet
A18: Fuel mass | B18: =Chrysalis!$B$80 -> 2.1281075e+12 | C18: kg | D18: Chrysalis sheet
A19: Exhaust velocity | B19: =Chrysalis!$B$19 -> 0.0333 | C19: × c | D19: Chrysalis sheet
A20: Distance | B20: =Chrysalis!$B$32 -> 4e+16 | C20: m | D20: Chrysalis sheet
A21: Relativistic lead of Chrysalis as drawn | B21: ='Lead table'!$Q$5*365.25 -> 8.1617448 | C21: days | D21: Lead table, row 5
A23: The roster arithmetic
A24: Quantity | B24: Value | C24: Unit | D24: Notes / source
A25: Watches over the journey | B25: =$B$10/$B$9 -> 40
A26: Person-watches available | B26: =$B$25*$B$8 -> 2400
A27: Watches per person | B27: =$B$26/$B$7 -> 1 | D27: Exactly 1 with the defaults: everyone serves once — 'one decade awake, thirty-nine asleep'
A28: Years awake per person | B28: =$B$27*$B$9 -> 10 | C28: years
A29: Years asleep per person | B29: =$B$10-$B$28 -> 390 | C29: years | D29: This is the time machine: the sleep is the jump
A30: Fraction of the people awake | B30: =$B$8/$B$7 -> 0.025
A31: Biological age at arrival (if storage halts ageing) | B31: =$B$16+$B$28 -> 35 | C31: years
A32: Calendar age at arrival | B32: =$B$16+$B$10 -> 425 | C32: years
A33: Pods occupied at any time | B33: =$B$7-$B$8 -> 2340 | C33: pods
A34: Pod volume, total | B34: =$B$33*$B$11 -> 7020 | C34: m³
A35: Holding power, total | B35: =$B$33*$B$12/1000 -> 351 | C35: kW | D35: Trivial beside a fusion plant; the hard part is the biology, not the power
A37: Less mass awake means faster — same fuel, lighter ship
A38: Quantity | B38: Value | C38: Unit | D38: Notes / source
A39: Pressurised volume needed, Vigil | B39: =$B$8*$B$13+$B$33*$B$11 -> 25020 | C39: m³
A40: Pressurised volume needed, everyone awake | B40: =$B$7*$B$13 -> 720000 | C40: m³
A41: Ratio | B41: =$B$39/$B$40 -> 0.03475
A42: Dry mass of the Vigil ship | B42: =$B$17*(1-$B$14*(1-$B$41)) -> 1241700000000 | C42: kg
A43: Δv with the same fuel, vₑ·ln(M₀/M₁) | B43: =$B$19*Constants!$B$7*LN(($B$42+$B$18)/$B$42) -> 9966858.4 | C43: m/s
A44: Cruise speed (half the Δv goes to braking) | B44: =$B$43/2 -> 4983429.2 | C44: m/s
...

Sheet Constants
A1: Constants and shared assumptions
A2: Physical constants (fixed) and the handful of shared assumptions every other sheet reads. Blue = input you can edit; yellow = an assumption worth questioning; black = formula.
A5: Physical constants
A6: Quantity | B6: Value | C6: Unit | D6: Notes / source
A7: Speed of light c | B7: 299792458 | C7: m/s | D7: SI exact value
A8: Standard gravity g₀ | B8: 9.80665 | C8: m/s² | D8: CGPM 1901 definition
A9: Gravitational constant G | B9: 6.6743e-11 | C9: m³ kg⁻¹ s⁻² | D9: CODATA 2018
A10: Julian year | B10: =365.25*86400 -> 31557600 | C10: s | D10: IAU: 365.25 days of 86,400 s
A11: Day | B11: 86400 | C11: s
A12: Light-year | B12: =$B$7*$B$10 -> 9.4607305e+15 | C12: m | D12: c × Julian year (IAU definition)
A13: Astronomical unit | B13: 149597870700 | C13: m | D13: IAU 2012 definition
A14: GM of the Sun | B14: 1.3271244e+20 | C14: m³/s² | D14: IAU 2015 nominal solar mass parameter
A15: GM of the Earth | B15: 398600441800000 | C15: m³/s² | D15: IAU 2015 nominal
A16: Earth equatorial radius | B16: 6378100 | C16: m | D16: IAU 2015 nominal
A17: Earth mass | B17: 5.9722e+24 | C17: kg | D17: NASA planetary fact sheet
A18: Jupiter mass | B18: 1.8982e+27 | C18: kg | D18: NASA planetary fact sheet
A19: Solar luminosity | B19: 3.828e+26 | C19: W | D19: IAU 2015 nominal
A20: Proton mass | B20: 1.6726219e-27 | C20: kg | D20: CODATA 2018
A21: Electron-volt | B21: 1.6021766e-19 | C21: J | D21: SI exact value
A22: Proton rest energy m_p c² | B22: =$B$20*$B$7^2 -> 1.5032776e-10 | C22: J
A23: …in MeV | B23: =$B$22/$B$21/1000000 -> 938.27209 | C23: MeV | D23: Should read 938.27
A24: Stefan–Boltzmann constant σ | B24: 5.6703744e-08 | C24: W m⁻² K⁻⁴ | D24: CODATA 2018
A25: TNT equivalent | B25: 4184000 | C25: J/kg | D25: Convention: 1 kg TNT = 4.184 MJ
A27: Shared assumptions (edit these)
A28: Quantity | B28: Value | C28: Unit | D28: Notes / source
A29: Interstellar hydrogen density n | B29: 1 | C29: atoms/cm³ | D29: Conservative. The Local Interstellar Cloud the Sun sits in is ~0.2 cm⁻³; set 0.2 for the optimistic case. Used by the Chrysalis, Tower and Nautilus sheets.
A30: Dust-to-gas mass ratio in the ISM | B30: 0.01 | D30: Standard interstellar value (~1%)
A31: Road-bike tyre pressure (for scale) | B31: 0.7 | C31: MPa | D31: ≈100 psi
A33: The project's own clocks, for scale
A34: Quantity | B34: Value | C34: Unit | D34: Notes / source
A35: Mount Greylock summit height | B35: 1063 | C35: m (NAVD88) | D35: The Greylock Time Machine design (claude/greylock-time-machine.md)
A36: Cambridge home-station height | B36: 6 | C36: m | D36: Same design note
A37: Harvard Jefferson tower (Pound–Rebka 1959) | B37: 22.5 | C37: m | D37: First laboratory measurement of gravitational time dilation
A38: Greylock rate difference g₀Δh/c² | B38: =$B$8*($B$35-$B$36)/$B$7^2 -> 1.1533318e-13 | C38: fraction | D38: Should read 1.153E-13 — the design note's figure
A39: …as nanoseconds per day (one 'Greylock') | B39: =$B$38*$B$11*1000000000 -> 9.9647865 | C39: ns/day | D39: Should read 9.96 ns/day
A40: Jefferson-tower rate difference g₀h/c² | B40: =$B$8*$B$37/$B$7^2 -> 2.4550582e-15 | C40: fraction
A41: …as nanoseconds per day (one 'Jefferson') | B41: =$B$40*$B$11*1000000000 -> 0.21211703 | C41: ns/day | D41: Should read 0.21 ns/day
A43: Materials for the hoop-stress check
A44: Material | B44: Density (kg/m³) | C44: Strength (MPa) | D44: Note
A45: Structural steel (A36) | B45: 7850 | C45: 250 | D45: Yield strength
...

Sheet Pendulum
A1: Pendulum — the ferry: the core is a return engine
A2: The ship that never arrives. It swings out at 1 g, turns, and comes home; whoever rides a swing steps off into Earth's future by the lead of that cycle. Chrysalis's shells become the terminal building and the core is an engine that always points home. Known physics end to end — the fare is the fuel.
A4: Inputs
A5: Quantity | B5: Value | C5: Unit | D5: Notes / source
A6: Proper acceleration | B6: 1 | C6: g | D6: Thrust gravity for the riders; 1 g keeps the terminal floors honest
A7: Years aboard per round trip (proper) | B7: 10 | C7: years | D7: Four equal phases: out-accel, out-brake, home-accel, home-brake — τ/4 each
A8: Cycles before refit | B8: 5 | C8: cycles | D8: Assumption
A9: Exhaust speed βₑ | B9: 1 | C9: × c | D9: βₑ = 1 is the perfect photon rocket — the floor on the fare, not an engine anyone has (Lead table note)
A10: Dry mass per rider | B10: =Chrysalis!$B$9/Chrysalis!$B$10 -> 1000000 | C10: t | D10: Chrysalis: 2.4 Gt / 2,400 people — a million tonnes of ship per rider
A12: One swing of the pendulum
A13: Quantity | B13: Value | C13: Unit | D13: Notes / source
A14: c/a | B14: =Constants!$B$7/($B$6*Constants!$B$8)/Constants!$B$10 -> 0.96871508 | C14: years
A15: Rapidity per phase, φ = (τ/4)/(c/a) | B15: =($B$7/4)/$B$14 -> 2.5807382
A16: Peak speed, tanh φ | B16: =TANH($B$15) -> 0.98859891 | C16: × c
A17: Furthest reach, 2(c/a)(cosh φ − 1) | B17: =2*$B$14*(COSH($B$15)-1) -> 10.929627 | C17: ly | D17: c²/a in light-years equals c/a in years
A18: Earth time per cycle, 4(c/a)·sinh φ | B18: =4*$B$14*SINH($B$15) -> 25.440716 | C18: years
A19: Lead per cycle | B19: =$B$18-$B$7 -> 15.440716 | C19: years
A20: …readable | B20: =IF($B$19<1/12,TEXT($B$19*365.25,"0.0")&" days",IF($B$19<1,TEXT($B$19*12,"0.0")&" months",TEXT($B$19,"0.0")&" years")) -> 15.4 years | D20: What one ticket buys
A21: Mass ratio per cycle, exp(4φ/βₑ) | B21: =EXP(4*$B$15/$B$9) -> 30422.957 | C21: × | D21: Four boosts of φ each; the relativistic rocket equation at its least merciful
A22: Fuel per tonne of ship per cycle | B22: =$B$21-1 -> 30421.957 | C22: t
A23: Fuel per rider per cycle | B23: =$B$22*$B$10 -> 3.0421957e+10 | C23: t | D23: The fare in perfect-photon propellant
A24: Fuel per rider per year of lead | B24: =$B$23/$B$19 -> 1.9702426e+09 | C24: t/yr | D24: The ferry's price list: tonnes of fuel per year of future delivered
A26: The timetable
A27: Cycle | B27: Ship clock at return (yr aboard) | C27: Earth calendar at return | D27: Cumulative lead
A28: =IF(1<=$B$8,1,"") -> 1 | B28: =IF(1<=$B$8,1*$B$7,"") -> 10 | C28: =IF(1<=$B$8,TEXT(Chrysalis!$B$22+1*$B$18,"0"),"") -> 2150 | D28: =IF(1<=$B$8,TEXT(1*($B$18-$B$7),"0.0")&" years ahead of staying home","") -> 15.4 years ahead of staying home
A29: =IF(2<=$B$8,2,"") -> 2 | B29: =IF(2<=$B$8,2*$B$7,"") -> 20 | C29: =IF(2<=$B$8,TEXT(Chrysalis!$B$22+2*$B$18,"0"),"") -> 2176 | D29: =IF(2<=$B$8,TEXT(2*($B$18-$B$7),"0.0")&" years ahead of staying home","") -> 30.9 years ahead of staying home
A30: =IF(3<=$B$8,3,"") -> 3 | B30: =IF(3<=$B$8,3*$B$7,"") -> 30 | C30: =IF(3<=$B$8,TEXT(Chrysalis!$B$22+3*$B$18,"0"),"") -> 2201 | D30: =IF(3<=$B$8,TEXT(3*($B$18-$B$7),"0.0")&" years ahead of staying home","") -> 46.3 years ahead of staying home
A31: =IF(4<=$B$8,4,"") -> 4 | B31: =IF(4<=$B$8,4*$B$7,"") -> 40 | C31: =IF(4<=$B$8,TEXT(Chrysalis!$B$22+4*$B$18,"0"),"") -> 2227 | D31: =IF(4<=$B$8,TEXT(4*($B$18-$B$7),"0.0")&" years ahead of staying home","") -> 61.8 years ahead of staying home
A32: =IF(5<=$B$8,5,"") -> 5 | B32: =IF(5<=$B$8,5*$B$7,"") -> 50 | C32: =IF(5<=$B$8,TEXT(Chrysalis!$B$22+5*$B$18,"0"),"") -> 2252 | D32: =IF(5<=$B$8,TEXT(5*($B$18-$B$7),"0.0")&" years ahead of staying home","") -> 77.2 years ahead of staying home
A33: =IF(6<=$B$8,6,"") | B33: =IF(6<=$B$8,6*$B$7,"") | C33: =IF(6<=$B$8,TEXT(Chrysalis!$B$22+6*$B$18,"0"),"") | D33: =IF(6<=$B$8,TEXT(6*($B$18-$B$7),"0.0")&" years ahead of staying home","")
A34: =IF(7<=$B$8,7,"") | B34: =IF(7<=$B$8,7*$B$7,"") | C34: =IF(7<=$B$8,TEXT(Chrysalis!$B$22+7*$B$18,"0"),"") | D34: =IF(7<=$B$8,TEXT(7*($B$18-$B$7),"0.0")&" years ahead of staying home","")
A35: =IF(8<=$B$8,8,"") | B35: =IF(8<=$B$8,8*$B$7,"") | C35: =IF(8<=$B$8,TEXT(Chrysalis!$B$22+8*$B$18,"0"),"") | D35: =IF(8<=$B$8,TEXT(8*($B$18-$B$7),"0.0")&" years ahead of staying home","")
A36: =IF(9<=$B$8,9,"") | B36: =IF(9<=$B$8,9*$B$7,"") | C36: =IF(9<=$B$8,TEXT(Chrysalis!$B$22+9*$B$18,"0"),"") | D36: =IF(9<=$B$8,TEXT(9*($B$18-$B$7),"0.0")&" years ahead of staying home","")
A37: =IF(10<=$B$8,10,"") | B37: =IF(10<=$B$8,10*$B$7,"") | C37: =IF(10<=$B$8,TEXT(Chrysalis!$B$22+10*$B$18,"0"),"") | D37: =IF(10<=$B$8,TEXT(10*($B$18-$B$7),"0.0")&" years ahead of staying home","")
A39: The arithmetic is brutal and honest: a ten-year ride returns fifteen Earth-years later for a mass ratio of thirty thousand — the Pendulum is the Tower with a return ticket, and the fare is why nobody runs a ferry to the future at 1 g. Short swings are nearly free (a two-year ride leads by a month) because the lead grows as sinh; the Vigil sheet sells the same future for the price of a nap. One redemption: with a Lantern mouth at each terminal the Pendulum stops being a ferry and becomes a subway.

Sheet Moult
A1: Moult — the ship that sheds its shells
A2: Chrysalis in reverse: instead of growing chambers (Nautilus), the ship jettisons each emptied shell as its people move inward or go under (Vigil), so the hull it must brake at Proxima is lighter than the hull it launched. Same fuel, same engine — the shed mass converts into cruise speed. No new physics; the quadratic below is the rocket equation with a lighter second burn.
A4: Inputs
A5: Quantity | B5: Value | C5: Unit | D5: Notes / source
A6: Fraction of dry mass moulted before the brake | B6: 0.5 | D6: Emptied shells, spent factories, outgrown nurseries — cast off after the burn out, before the brake
A7: Dry mass at launch | B7: =Chrysalis!$B$31 -> 2400000000000 | C7: kg | D7: Chrysalis sheet
A8: Fuel | B8: =Chrysalis!$B$80 -> 2.1281075e+12 | C8: kg | D8: The Chrysalis sheet's own fuel load
A9: Exhaust velocity | B9: =Chrysalis!$B$19*Constants!$B$7 -> 9983088.9 | C9: m/s
A10: Distance | B10: =Chrysalis!$B$32 -> 4e+16 | C10: m
A12: Two burns with a moult between
A13: Quantity | B13: Value | C13: Unit | D13: Notes / source
A14: Dry mass at the brake | B14: =$B$7*(1-$B$6) -> 1200000000000 | C14: kg
A15: X = e^(v/vₑ), root of M₁′X² + (M₀ − M₁′)X − (M₀ + F) = 0 | B15: =(-($B$7-$B$14)+SQRT(($B$7-$B$14)^2+4*$B$14*($B$7+$B$8)))/(2*$B$14) -> 1.5058472 | D15: Accelerate at full mass, brake at moulted mass, same total fuel
A16: Cruise speed | B16: =$B$9*LN($B$15) -> 4086633.8 | C16: m/s
A17: …as a fraction of c | B17: =$B$16/Constants!$B$7 -> 0.013631543 | C17: × c
A18: Journey time | B18: =$B$10/$B$16/Constants!$B$10 -> 310.16322 | C18: years
A19: Years saved vs Chrysalis as drawn | B19: =Chrysalis!$B$13-$B$18 -> 89.836775 | C19: years
A20: Relativistic lead at arrival, (β²/2)·T | B20: =$B$17^2/2*$B$18*365.25 -> 10.525447 | C20: days | D20: Faster and shorter, yet more lead: the rate wins over the duration
A21: Lead gained over Chrysalis | B21: ='Lead table'!$Q$5*-365.25+$B$20 -> 2.3637027 | C21: days
A22: Control: speed at 0% moult, vₑ·ln √(1+F/M₀) | B22: =$B$9*LN(SQRT(1+$B$8/$B$7))/Constants!$B$7 -> 0.010570008 | C22: × c | D22: Equals Chrysalis's β = 0.0106 exactly — the sheet contains its own control
A24: The moulting calendar — every shed fraction at once
A25: Moult fraction | B25: Cruise β | C25: Journey (yr) | D25: Years saved / lead
A26: 0.1 | B26: =$B$9*LN((-($B$7-$B$7*(1-$A26))+SQRT(($B$7-$B$7*(1-$A26))^2+4*$B$7*(1-$A26)*($B$7+$B$8)))/(2*$B$7*(1-$A26)))/Constants!$B$7 -> 0.011046841 | C26: =$B$10/($B26*Constants!$B$7)/Constants!$B$10 -> 382.73416 | D26: =TEXT(Chrysalis!$B$13-$C26,"0")&" yr saved; lead "&TEXT($B26^2/2*$C26*365.25,"0.0")&" days" -> 17 yr saved; lead 8.5 days
A27: 0.2 | B27: =$B$9*LN((-($B$7-$B$7*(1-$A27))+SQRT(($B$7-$B$7*(1-$A27))^2+4*$B$7*(1-$A27)*($B$7+$B$8)))/(2*$B$7*(1-$A27)))/Constants!$B$7 -> 0.011577851 | C27: =$B$10/($B27*Constants!$B$7)/Constants!$B$10 -> 365.18033 | D27: =TEXT(Chrysalis!$B$13-$C27,"0")&" yr saved; lead "&TEXT($B27^2/2*$C27*365.25,"0.0")&" days" -> 35 yr saved; lead 8.9 days
A28: 0.3 | B28: =$B$9*LN((-($B$7-$B$7*(1-$A28))+SQRT(($B$7-$B$7*(1-$A28))^2+4*$B$7*(1-$A28)*($B$7+$B$8)))/(2*$B$7*(1-$A28)))/Constants!$B$7 -> 0.012174453 | C28: =$B$10/($B28*Constants!$B$7)/Constants!$B$10 -> 347.28486 | D28: =TEXT(Chrysalis!$B$13-$C28,"0")&" yr saved; lead "&TEXT($B28^2/2*$C28*365.25,"0.0")&" days" -> 53 yr saved; lead 9.4 days
A29: 0.4 | B29: =$B$9*LN((-($B$7-$B$7*(1-$A29))+SQRT(($B$7-$B$7*(1-$A29))^2+4*$B$7*(1-$A29)*($B$7+$B$8)))/(2*$B$7*(1-$A29)))/Constants!$B$7 -> 0.012851955 | C29: =$B$10/($B29*Constants!$B$7)/Constants!$B$10 -> 328.97745 | D29: =TEXT(Chrysalis!$B$13-$C29,"0")&" yr saved; lead "&TEXT($B29^2/2*$C29*365.25,"0.0")&" days" -> 71 yr saved; lead 9.9 days
A30: 0.5 | B30: =$B$9*LN((-($B$7-$B$7*(1-$A30))+SQRT(($B$7-$B$7*(1-$A30))^2+4*$B$7*(1-$A30)*($B$7+$B$8)))/(2*$B$7*(1-$A30)))/Constants!$B$7 -> 0.013631543 | C30: =$B$10/($B30*Constants!$B$7)/Constants!$B$10 -> 310.16322 | D30: =TEXT(Chrysalis!$B$13-$C30,"0")&" yr saved; lead "&TEXT($B30^2/2*$C30*365.25,"0.0")&" days" -> 90 yr saved; lead 10.5 days
A31: 0.6 | B31: =$B$9*LN((-($B$7-$B$7*(1-$A31))+SQRT(($B$7-$B$7*(1-$A31))^2+4*$B$7*(1-$A31)*($B$7+$B$8)))/(2*$B$7*(1-$A31)))/Constants!$B$7 -> 0.014543753 | C31: =$B$10/($B31*Constants!$B$7)/Constants!$B$10 -> 290.70924 | D31: =TEXT(Chrysalis!$B$13-$C31,"0")&" yr saved; lead "&TEXT($B31^2/2*$C31*365.25,"0.0")&" days" -> 109 yr saved; lead 11.2 days
A32: 0.7 | B32: =$B$9*LN((-($B$7-$B$7*(1-$A32))+SQRT(($B$7-$B$7*(1-$A32))^2+4*$B$7*(1-$A32)*($B$7+$B$8)))/(2*$B$7*(1-$A32)))/Constants!$B$7 -> 0.015634959 | C32: =$B$10/($B32*Constants!$B$7)/Constants!$B$10 -> 270.41985 | D32: =TEXT(Chrysalis!$B$13-$C32,"0")&" yr saved; lead "&TEXT($B32^2/2*$C32*365.25,"0.0")&" days" -> 130 yr saved; lead 12.1 days
A33: 0.8 | B33: =$B$9*LN((-($B$7-$B$7*(1-$A33))+SQRT(($B$7-$B$7*(1-$A33))^2+4*$B$7*(1-$A33)*($B$7+$B$8)))/(2*$B$7*(1-$A33)))/Constants!$B$7 -> 0.016980811 | C33: =$B$10/($B33*Constants!$B$7)/Constants!$B$10 -> 248.98712 | D33: =TEXT(Chrysalis!$B$13-$C33,"0")&" yr saved; lead "&TEXT($B33^2/2*$C33*365.25,"0.0")&" days" -> 151 yr saved; lead 13.1 days
A34: 0.9 | B34: =$B$9*LN((-($B$7-$B$7*(1-$A34))+SQRT(($B$7-$B$7*(1-$A34))^2+4*$B$7*(1-$A34)*($B$7+$B$8)))/(2*$B$7*(1-$A34)))/Constants!$B$7 -> 0.018718212 | C34: =$B$10/($B34*Constants!$B$7)/Constants!$B$10 -> 225.87645 | D34: =TEXT(Chrysalis!$B$13-$C34,"0")&" yr saved; lead "&TEXT($B34^2/2*$C34*365.25,"0.0")&" days" -> 174 yr saved; lead 14.5 days
A36: What a moult sheds
